Traceback (most recent call last):
  File "/Users/jkitchin/opt/anaconda3/lib/python3.9/site-packages/jupyter_cache/executors/utils.py", line 58, in single_nb_execution
    executenb(
  File "/Users/jkitchin/opt/anaconda3/lib/python3.9/site-packages/nbclient/client.py", line 1204, in execute
    return NotebookClient(nb=nb, resources=resources, km=km, **kwargs).execute()
  File "/Users/jkitchin/opt/anaconda3/lib/python3.9/site-packages/nbclient/util.py", line 84, in wrapped
    return just_run(coro(*args, **kwargs))
  File "/Users/jkitchin/opt/anaconda3/lib/python3.9/site-packages/nbclient/util.py", line 62, in just_run
    return loop.run_until_complete(coro)
  File "/Users/jkitchin/opt/anaconda3/lib/python3.9/asyncio/base_events.py", line 647, in run_until_complete
    return future.result()
  File "/Users/jkitchin/opt/anaconda3/lib/python3.9/site-packages/nbclient/client.py", line 663, in async_execute
    await self.async_execute_cell(
  File "/Users/jkitchin/opt/anaconda3/lib/python3.9/site-packages/nbclient/client.py", line 965, in async_execute_cell
    await self._check_raise_for_error(cell, cell_index, exec_reply)
  File "/Users/jkitchin/opt/anaconda3/lib/python3.9/site-packages/nbclient/client.py", line 862, in _check_raise_for_error
    raise CellExecutionError.from_cell_and_msg(cell, exec_reply_content)
nbclient.exceptions.CellExecutionError: An error occurred while executing the following cell:
------------------
import numpy as np
import json

import matplotlib.pyplot as plt

with open('../07-intermediate-sklearn/data.json') as f:
    data = json.load(f)

X = np.array([data['distance']]).T
y = data['energy']

from sklearn.neural_network import MLPRegressor

model = MLPRegressor(hidden_layer_sizes=(3,), activation='tanh', solver='lbfgs')
model.fit(X, y)

dfit = np.linspace(1.5, 7)

plt.plot(data['distance'], data['energy'], 'bo',
         dfit, model.predict(dfit[:, None]))

plt.xlabel('distance')
plt.ylabel('energy');
------------------

[0;31m---------------------------------------------------------------------------[0m
[0;31mFileNotFoundError[0m                         Traceback (most recent call last)
Input [0;32mIn [1][0m, in [0;36m<cell line: 6>[0;34m()[0m
[1;32m      2[0m [38;5;28;01mimport[39;00m [38;5;21;01mjson[39;00m
[1;32m      4[0m [38;5;28;01mimport[39;00m [38;5;21;01mmatplotlib[39;00m[38;5;21;01m.[39;00m[38;5;21;01mpyplot[39;00m [38;5;28;01mas[39;00m [38;5;21;01mplt[39;00m
[0;32m----> 6[0m [38;5;28;01mwith[39;00m [38;5;28;43mopen[39;49m[43m([49m[38;5;124;43m'[39;49m[38;5;124;43m../07-intermediate-sklearn/data.json[39;49m[38;5;124;43m'[39;49m[43m)[49m [38;5;28;01mas[39;00m f:
[1;32m      7[0m     data [38;5;241m=[39m json[38;5;241m.[39mload(f)
[1;32m      9[0m X [38;5;241m=[39m np[38;5;241m.[39marray([data[[38;5;124m'[39m[38;5;124mdistance[39m[38;5;124m'[39m]])[38;5;241m.[39mT

[0;31mFileNotFoundError[0m: [Errno 2] No such file or directory: '../07-intermediate-sklearn/data.json'
FileNotFoundError: [Errno 2] No such file or directory: '../07-intermediate-sklearn/data.json'

